<?xml version="1.0" encoding="utf-8"?>
<!-- This URDF was automatically created by SolidWorks to URDF Exporter! Originally created by Stephen Brawner (brawner@gmail.com) 
     Commit Version: 1.6.0-4-g7f85cfe  Build Version: 1.6.7995.38578
     For more information, please see http://wiki.ros.org/sw_urdf_exporter -->
<robot
  name="Robotic_Arm">
  <link
    name="base_link">
    <inertial>
      <origin
        xyz="0.70723 0.89479 1.3289"
        rpy="0 0 0" />
      <mass
        value="0.19084" />
      <inertia
        ixx="0.00014713"
        ixy="6.8937E-06"
        ixz="-8.9675E-07"
        iyy="0.00026594"
        iyz="-1.5506E-05"
        izz="0.00014875" />
    </inertial>
    <visual>
      <origin
        xyz="0 0 0"
        rpy="0 0 0" />
      <geometry>
        <mesh
          filename="package://Robotic_Arm/meshes/base_link.STL" />
      </geometry>
      <material
        name="">
        <color
          rgba="0.79216 0.81961 0.93333 1" />
      </material>
    </visual>
    <collision>
      <origin
        xyz="0 0 0"
        rpy="0 0 0" />
      <geometry>
        <mesh
          filename="package://Robotic_Arm/meshes/base_link.STL" />
      </geometry>
    </collision>
  </link>
  <link
    name="lower_arm">
    <inertial>
      <origin
        xyz="-0.034789 0.052024 4.4209E-05"
        rpy="0 0 0" />
      <mass
        value="0.19613" />
      <inertia
        ixx="0.00038821"
        ixy="0.00032912"
        ixz="5.654E-07"
        iyy="0.00038835"
        iyz="-6.0057E-07"
        izz="0.00072024" />
    </inertial>
    <visual>
      <origin
        xyz="0 0 0"
        rpy="0 0 0" />
      <geometry>
        <mesh
          filename="package://Robotic_Arm/meshes/lower_arm.STL" />
      </geometry>
      <material
        name="">
        <color
          rgba="0.79216 0.81961 0.93333 1" />
      </material>
    </visual>
    <collision>
      <origin
        xyz="0 0 0"
        rpy="0 0 0" />
      <geometry>
        <mesh
          filename="package://Robotic_Arm/meshes/lower_arm.STL" />
      </geometry>
    </collision>
  </link>
  <joint
    name="joint0"
    type="revolute">
    <origin
      xyz="0.70796 -1.3272 0.9075"
      rpy="1.6757 0.094954 1.9904" />
    <parent
      link="base_link" />
    <child
      link="lower_arm" />
    <axis
      xyz="0 1 0" />
    <limit
      lower="-3.14"
      upper="3.14"
      effort="10"
      velocity="1" />
  </joint>
  <link
    name="upper_arm">
    <inertial>
      <origin
        xyz="0.030278 0.032273 -0.019925"
        rpy="0 0 0" />
      <mass
        value="0.081835" />
      <inertia
        ixx="9.6287E-05"
        ixy="-7.8192E-05"
        ixz="-1.6357E-06"
        iyy="7.9895E-05"
        iyz="-1.7788E-06"
        izz="0.00017026" />
    </inertial>
    <visual>
      <origin
        xyz="0 0 0"
        rpy="0 0 0" />
      <geometry>
        <mesh
          filename="package://Robotic_Arm/meshes/upper_arm.STL" />
      </geometry>
      <material
        name="">
        <color
          rgba="0.79216 0.81961 0.93333 1" />
      </material>
    </visual>
    <collision>
      <origin
        xyz="0 0 0"
        rpy="0 0 0" />
      <geometry>
        <mesh
          filename="package://Robotic_Arm/meshes/upper_arm.STL" />
      </geometry>
    </collision>
  </link>
  <joint
    name="joint1"
    type="revolute">
    <origin
      xyz="-0.1 0.12129 0"
      rpy="0 0 -0.97771" />
    <parent
      link="lower_arm" />
    <child
      link="upper_arm" />
    <axis
      xyz="0 0 1" />
    <limit
      lower="-3.14"
      upper="3.14"
      effort="10"
      velocity="1" />
  </joint>
  <link
    name="shoulder_drive">
    <inertial>
      <origin
        xyz="0.0053519 -4.4717E-05 0.010345"
        rpy="0 0 0" />
      <mass
        value="0.036284" />
      <inertia
        ixx="1.6274E-05"
        ixy="-5.7101E-10"
        ixz="2.109E-07"
        iyy="1.6305E-05"
        iyz="-1.2692E-08"
        izz="4.537E-06" />
    </inertial>
    <visual>
      <origin
        xyz="0 0 0"
        rpy="0 0 0" />
      <geometry>
        <mesh
          filename="package://Robotic_Arm/meshes/shoulder_drive.STL" />
      </geometry>
      <material
        name="">
        <color
          rgba="0.79216 0.81961 0.93333 1" />
      </material>
    </visual>
    <collision>
      <origin
        xyz="0 0 0"
        rpy="0 0 0" />
      <geometry>
        <mesh
          filename="package://Robotic_Arm/meshes/shoulder_drive.STL" />
      </geometry>
    </collision>
  </link>
  <joint
    name="joint2"
    type="revolute">
    <origin
      xyz="0.08 0.09 0"
      rpy="1.9556 -1.5708 0" />
    <parent
      link="upper_arm" />
    <child
      link="shoulder_drive" />
    <axis
      xyz="1 0 0" />
    <limit
      lower="-3.14"
      upper="3.14"
      effort="10"
      velocity="1" />
  </joint>
  <link
    name="rotary_yoke">
    <inertial>
      <origin
        xyz="0.0034544 -8.8589E-10 -1.5216E-10"
        rpy="0 0 0" />
      <mass
        value="0.015723" />
      <inertia
        ixx="4.9761E-06"
        ixy="2.7011E-13"
        ixz="1.3689E-13"
        iyy="8.6886E-06"
        iyz="1.0867E-12"
        izz="6.6823E-06" />
    </inertial>
    <visual>
      <origin
        xyz="0 0 0"
        rpy="0 0 0" />
      <geometry>
        <mesh
          filename="package://Robotic_Arm/meshes/rotary_yoke.STL" />
      </geometry>
      <material
        name="">
        <color
          rgba="0.79216 0.81961 0.93333 1" />
      </material>
    </visual>
    <collision>
      <origin
        xyz="0 0 0"
        rpy="0 0 0" />
      <geometry>
        <mesh
          filename="package://Robotic_Arm/meshes/rotary_yoke.STL" />
      </geometry>
    </collision>
  </link>
  <joint
    name="joint3"
    type="revolute">
    <origin
      xyz="0.005 0 0.077514"
      rpy="1.1002 1.5708 0" />
    <parent
      link="shoulder_drive" />
    <child
      link="rotary_yoke" />
    <axis
      xyz="1 0 0" />
    <limit
      lower="-3.14"
      upper="3.14"
      effort="10"
      velocity="1" />
  </joint>
  <link
    name="wrist_module">
    <inertial>
      <origin
        xyz="0.0052933 6.3561E-10 3.6458E-10"
        rpy="0 0 0" />
      <mass
        value="0.034187" />
      <inertia
        ixx="3.7152E-06"
        ixy="4.4265E-13"
        ixz="1.2545E-13"
        iyy="8.9897E-06"
        iyz="-9.6955E-13"
        izz="9.0316E-06" />
    </inertial>
    <visual>
      <origin
        xyz="0 0 0"
        rpy="0 0 0" />
      <geometry>
        <mesh
          filename="package://Robotic_Arm/meshes/wrist_module.STL" />
      </geometry>
      <material
        name="">
        <color
          rgba="0.79216 0.81961 0.93333 1" />
      </material>
    </visual>
    <collision>
      <origin
        xyz="0 0 0"
        rpy="0 0 0" />
      <geometry>
        <mesh
          filename="package://Robotic_Arm/meshes/wrist_module.STL" />
      </geometry>
    </collision>
  </link>
  <joint
    name="joint4"
    type="revolute">
    <origin
      xyz="-0.025486 0 0"
      rpy="0 0 1.8687" />
    <parent
      link="rotary_yoke" />
    <child
      link="wrist_module" />
    <axis
      xyz="0 0 1" />
    <limit
      lower="-3.14"
      upper="3.14"
      effort="8"
      velocity="1" />
  </joint>
  <link
    name="gripper_actuator">
    <inertial>
      <origin
        xyz="-3.7917E-09 -9.0172E-09 0.0059505"
        rpy="0 0 0" />
      <mass
        value="0.015789" />
      <inertia
        ixx="1.6581E-06"
        ixy="4.1866E-12"
        ixz="5.5925E-13"
        iyy="1.6959E-06"
        iyz="8.6177E-13"
        izz="1.8592E-06" />
    </inertial>
    <visual>
      <origin
        xyz="0 0 0"
        rpy="0 0 0" />
      <geometry>
        <mesh
          filename="package://Robotic_Arm/meshes/gripper_actuator.STL" />
      </geometry>
      <material
        name="">
        <color
          rgba="0.79216 0.81961 0.93333 1" />
      </material>
    </visual>
    <collision>
      <origin
        xyz="0 0 0"
        rpy="0 0 0" />
      <geometry>
        <mesh
          filename="package://Robotic_Arm/meshes/gripper_actuator.STL" />
      </geometry>
    </collision>
  </link>
  <joint
    name="joint5"
    type="revolute">
    <origin
      xyz="0.03356 0 0"
      rpy="-1.5708 0.5658 -1.5708" />
    <parent
      link="wrist_module" />
    <child
      link="gripper_actuator" />
    <axis
      xyz="0 0 1" />
    <limit
      lower="-3.14"
      upper="3.14"
      effort="10"
      velocity="1" />
  </joint>
  <link
    name="gripper_1">
    <inertial>
      <origin
        xyz="0.018895 0.0012108 5.4008E-08"
        rpy="0 0 0" />
      <mass
        value="0.0029088" />
      <inertia
        ixx="5.5054E-08"
        ixy="-3.6466E-08"
        ixz="-5.9482E-12"
        iyy="5.6195E-07"
        iyz="6.3354E-14"
        izz="5.2896E-07" />
    </inertial>
    <visual>
      <origin
        xyz="0 0 0"
        rpy="0 0 0" />
      <geometry>
        <mesh
          filename="package://Robotic_Arm/meshes/gripper_1.STL" />
      </geometry>
      <material
        name="">
        <color
          rgba="0.79216 0.81961 0.93333 1" />
      </material>
    </visual>
    <collision>
      <origin
        xyz="0 0 0"
        rpy="0 0 0" />
      <geometry>
        <mesh
          filename="package://Robotic_Arm/meshes/gripper_1.STL" />
      </geometry>
    </collision>
  </link>
  <joint
    name="joint6"
    type="revolute">
    <origin
      xyz="-0.011 0 0.02344"
      rpy="1.5708 -1.5034 0" />
    <parent
      link="gripper_actuator" />
    <child
      link="gripper_1" />
    <axis
      xyz="0 0 1" />
    <limit
      lower="-0.2"
      upper="1.57"
      effort="2"
      velocity="1" />
  </joint>
  <link
    name="gripper_2">
    <inertial>
      <origin
        xyz="0.018895 0.0012108 5.2626E-08"
        rpy="0 0 0" />
      <mass
        value="0.0029088" />
      <inertia
        ixx="5.5055E-08"
        ixy="-3.6466E-08"
        ixz="-5.9756E-12"
        iyy="5.6195E-07"
        iyz="3.1914E-14"
        izz="5.2896E-07" />
    </inertial>
    <visual>
      <origin
        xyz="0 0 0"
        rpy="0 0 0" />
      <geometry>
        <mesh
          filename="package://Robotic_Arm/meshes/gripper_2.STL" />
      </geometry>
      <material
        name="">
        <color
          rgba="0.79216 0.81961 0.93333 1" />
      </material>
    </visual>
    <collision>
      <origin
        xyz="0 0 0"
        rpy="0 0 0" />
      <geometry>
        <mesh
          filename="package://Robotic_Arm/meshes/gripper_2.STL" />
      </geometry>
    </collision>
  </link>
  <joint
    name="joint7"
    type="revolute">
    <origin
      xyz="0.011 0 0.02344"
      rpy="1.5708 -1.5034 3.1416" />
    <parent
      link="gripper_actuator" />
    <child
      link="gripper_2" />
    <axis
      xyz="0 0 1" />
    <limit
      lower="-0.2"
      upper="1.57"
      effort="2"
      velocity="1" />
  </joint>
</robot>